<?xml version="1.0" ?>
<robot name="centauro" version="1.0">
  <material name="black">
    <color rgba="0.4 0.4 0.4 1.0"/>
  </material>
  <material name="dark">
    <color rgba="0.1 0.1 0.1 1.0"/>
  </material>
  <material name="dark_grey">
    <color rgba="0.2 0.2 0.2 1.0"/>
  </material>
  <link name="base_link"/>
  <link name="pelvis">
    <inertial>
      <origin xyz="-0.0016320207 0.0026534004000000003 0.079167428" rpy="0 0 0"/>
      <mass value="26.584529"/>
      <inertia ixx="0.39195477" ixy="0.024781258999999996" ixz="0.017108606999999998" iyy="1.0000708999999999" iyz="0.0052627106000000005" izz="1.0679988999999999"/>
    </inertial>
    <visual>
      <origin xyz="0.0 0.0 0.0" rpy="0.0 0.0 0.0"/>
      <geometry>
        <mesh filename="package://centauro_urdf/meshes/v2/pelvis.stl" scale="0.001 0.001 0.001"/>
      </geometry>
    </visual>
    <collision>
      <origin xyz="-0.005084999999999992 2.00284e-07 0.06057945" rpy="3.141584708121066 1.5478729636744712 3.14158452386424"/>
      <geometry>
        <box size="0.32 0.34 0.64" radius="0.213204" length="0.38594139791384763"/>
      </geometry>
    </collision>
  </link>
  <link name="imu_link"/>
  <joint name="imu_joint" type="fixed">
    <origin xyz="0.248316 0.0 0.015" rpy="0.0 0.0 0.0"/>
    <parent link="pelvis"/>
    <child link="imu_link"/>
  </joint>
  <joint name="base_joint" type="fixed">
    <origin xyz="0.0 0.0 0.0" rpy="0.0 0.0 0.0"/>
    <parent link="pelvis"/>
    <child link="base_link"/>
  </joint>
  <link name="torso_2">
    <inertial>
      <origin xyz="-0.019497794 0.0045317835 0.13768283" rpy="0 0 0"/>
      <mass value="12.553731"/>
      <inertia ixx="0.063643392" ixy="8.939e-05" ixz="-0.00086873" iyy="0.02680235" iyz="-4.657e-05" izz="0.04743015"/>
    </inertial>
    <visual>
      <origin xyz="0.0 0.0 0.0" rpy="0.0 0.0 0.0"/>
      <geometry>
        <mesh filename="package://centauro_urdf/meshes/link1_no_head.stl" scale="0.001 0.001 0.001"/>
      </geometry>
    </visual>
    <collision>
      <origin xyz="-3.2165000000000015e-05 9.785000000000002e-05 0.07465275" rpy="1.5666391113102787 -0.01588146658428072 -0.0158155835137567"/>
      <geometry>
        <cylinder radius="0.158224" length="0.09543675990850982"/>
      </geometry>
    </collision>
    <collision>
      <origin xyz="0.000726 0.047810 0.074454" rpy="1.5666391113102787 -0.01588146658428072 -0.0158155835137567"/>
      <geometry>
        <sphere radius="0.158224"/>
      </geometry>
    </collision>
    <collision>
      <origin xyz="-0.000790 -0.047614 0.074851" rpy="1.5666391113102787 -0.01588146658428072 -0.0158155835137567"/>
      <geometry>
        <sphere radius="0.158224"/>
      </geometry>
    </collision>
  </link>
  <joint name="torso_yaw" type="revolute">
    <origin xyz="0.2 0.0 0.256" rpy="0 0 0"/>
    <axis xyz="0.0 0.0 1.0"/>
    <parent link="pelvis"/>
    <child link="torso_2"/>
    <limit effort="147.0" lower="-2.618" upper="2.618" velocity="5.7"/>
  </joint>
  <link name="arm1_1">
    <inertial>
      <origin xyz="-0.0074457212 0.03410796 0.00010978102" rpy="0 0 0"/>
      <mass value="1.9628675"/>
      <inertia ixx="0.0053547717" ixy="0.00036428926" ixz="1.5089568e-05" iyy="0.0033923328" iyz="5.5692312e-05" izz="0.0068921413"/>
    </inertial>
    <visual>
      <origin xyz="0.0 0.0 0.0" rpy="0.0 0.0 0.0"/>
      <geometry>
        <mesh filename="package://centauro_urdf/meshes/ShoulderPitch.STL" scale="0.001 -0.001 0.001"/>
      </geometry>
      <material name="dark_grey"/>
    </visual>
    <collision>
      <origin xyz="0.017831411999999998 0.05324115 2.3169000000000008e-05" rpy="-1.6903347176271586 1.4526491831510902 -1.5721974565036339"/>
      <geometry>
        <cylinder radius="0.0698859" length="0.03739768494560427"/>
      </geometry>
    </collision>
    <collision>
      <origin xyz="-0.000737 0.051053 0.000286" rpy="-1.6903347176271586 1.4526491831510902 -1.5721974565036339"/>
      <geometry>
        <sphere radius="0.0698859"/>
      </geometry>
    </collision>
    <collision>
      <origin xyz="0.036400 0.055429 -0.000240" rpy="-1.6903347176271586 1.4526491831510902 -1.5721974565036339"/>
      <geometry>
        <sphere radius="0.0698859"/>
      </geometry>
    </collision>
  </link>
  <link name="arm1_2">
    <inertial>
      <origin xyz="0.058142302 5.7450803e-05 -0.077477683" rpy="0 0 0"/>
      <mass value="1.8595811"/>
      <inertia ixx="0.013776643" ixy="3.7788675e-05" ixz="0.0037690171" iyy="0.015677464" iyz="-9.4893549e-06" izz="0.0046317657"/>
    </inertial>
    <visual>
      <origin xyz="0.0 0.0 0.0" rpy="0.0 0.0 0.0"/>
      <geometry>
        <mesh filename="package://centauro_urdf/meshes/ShoulderRoll.STL" scale="0.001 -0.001 0.001"/>
      </geometry>
    </visual>
    <collision>
      <origin xyz="0.0637382 4.0379999999999995e-07 -0.064359175" rpy="3.141581408692036 0.43013736369295724 3.141541177080914"/>
      <geometry>
        <cylinder radius="0.0700645" length="0.12799269981445732"/>
      </geometry>
    </collision>
    <collision>
      <origin xyz="0.037052 0.000001 -0.006192" rpy="3.141581408692036 0.43013736369295724 3.141541177080914"/>
      <geometry>
        <sphere radius="0.0700645"/>
      </geometry>
    </collision>
    <collision>
      <origin xyz="0.090424 -0.000000 -0.122526" rpy="3.141581408692036 0.43013736369295724 3.141541177080914"/>
      <geometry>
        <sphere radius="0.0700645"/>
      </geometry>
    </collision>
  </link>
  <link name="arm1_3">
    <inertial>
      <origin xyz="0.014625194 0.0008172672 -0.028333545" rpy="0 0 0"/>
      <mass value="1.6678109"/>
      <inertia ixx="0.0064480435" ixy="-0.00015639093" ixz="0.0012205359" iyy="0.0073372077" iyz="8.9941532e-05" izz="0.0036738448"/>
    </inertial>
    <visual>
      <origin xyz="0.0 0.0 0.0" rpy="0.0 0.0 0.0"/>
      <geometry>
        <mesh filename="package://centauro_urdf/meshes/ShoulderYaw.STL" scale="0.001 -0.001 0.001"/>
      </geometry>
      <material name="dark_grey"/>
    </visual>
    <collision>
      <origin xyz="0.0073075385949999995 -0.0040911384949999996 -0.03662884" rpy="3.0024238046134086 0.2429098209130052 2.103907539504161"/>
      <geometry>
        <cylinder radius="0.0896121" length="0.06082252644344949"/>
      </geometry>
    </collision>
    <collision>
      <origin xyz="-0.000007 0.000004 -0.007396" rpy="3.0024238046134086 0.2429098209130052 2.103907539504161"/>
      <geometry>
        <sphere radius="0.0896121"/>
      </geometry>
    </collision>
    <collision>
      <origin xyz="0.014622 -0.008186 -0.065862" rpy="3.0024238046134086 0.2429098209130052 2.103907539504161"/>
      <geometry>
        <sphere radius="0.0896121"/>
      </geometry>
    </collision>
  </link>
  <link name="arm1_4">
    <inertial>
      <origin xyz="-0.0076833067 -0.040302205 -0.043492779" rpy="0 0 0"/>
      <mass value="1.3157289"/>
      <inertia ixx="0.004330394" ixy="-0.00011737391" ixz="-0.00041923199" iyy="0.0038539919" iyz="-0.00079573038" izz="0.0017594689"/>
    </inertial>
    <visual>
      <origin xyz="0.0 0.0 0.0" rpy="0.0 0.0 0.0"/>
      <geometry>
        <mesh filename="package://centauro_urdf/meshes/Elbow.STL" scale="0.001 -0.001 0.001"/>
      </geometry>
    </visual>
    <collision>
      <origin xyz="-0.00746020465 -0.0408499 -0.0404292381" rpy="-0.33854605247629793 0.17337814940326016 -0.029704070188628324"/>
      <geometry>
        <cylinder radius="0.0600429" length="0.08713418572944408"/>
      </geometry>
    </collision>
    <collision>
      <origin xyz="-0.014976 -0.055102 -0.080907" rpy="-0.33854605247629793 0.17337814940326016 -0.029704070188628324"/>
      <geometry>
        <sphere radius="0.0600429"/>
      </geometry>
    </collision>
    <collision>
      <origin xyz="0.000056 -0.026598 0.000049" rpy="-0.33854605247629793 0.17337814940326016 -0.029704070188628324"/>
      <geometry>
        <sphere radius="0.0600429"/>
      </geometry>
    </collision>
  </link>
  <link name="arm1_5">
    <inertial>
      <origin xyz="-0.00011079615 0.011590836 -0.07816026" rpy="0 0 0"/>
      <mass value="1.4908547"/>
      <inertia ixx="0.0085692128" ixy="1.7856252e-05" ixz="1.9379365e-05" iyy="0.0077454159" iyz="-0.00032860094" izz="0.0027441921"/>
    </inertial>
    <visual>
      <origin xyz="0.0 0.0 0.0" rpy="0.0 0.0 0.0"/>
      <geometry>
        <mesh filename="package://centauro_urdf/meshes/Forearm.STL" scale="0.001 -0.001 0.001"/>
      </geometry>
      <material name="dark_grey"/>
    </visual>
    <collision>
      <origin xyz="-3.7982785e-06 0.00576208 -0.08227100000000001" rpy="-0.1950499967900825 0.00010897079569875528 -1.0661198134352675e-05"/>
      <geometry>
        <cylinder radius="0.0804108" length="0.08434739747702645"/>
      </geometry>
    </collision>
    <collision>
      <origin xyz="-0.000008 -0.002412 -0.123645" rpy="-0.1950499967900825 0.00010897079569875528 -1.0661198134352675e-05"/>
      <geometry>
        <sphere radius="0.0804108"/>
      </geometry>
    </collision>
    <collision>
      <origin xyz="0.000001 0.013936 -0.040897" rpy="-0.1950499967900825 0.00010897079569875528 -1.0661198134352675e-05"/>
      <geometry>
        <sphere radius="0.0804108"/>
      </geometry>
    </collision>
  </link>
  <link name="arm1_6">
    <inertial>
      <origin xyz="-4.6502396e-06 -0.038014094 -0.069926878" rpy="0 0 0"/>
      <mass value="1.1263612"/>
      <inertia ixx="0.0051871784" ixy="2.724437e-05" ixz="2.2833496e-06" iyy="0.0048037789" iyz="-0.00072165653" izz="0.0012771388"/>
    </inertial>
    <visual>
      <origin xyz="0.0 0.0 0.0" rpy="0.0 0.0 0.0"/>
      <geometry>
        <mesh filename="package://centauro_urdf/meshes/wrist_pitch_right.stl" scale="0.001 -0.001 0.001"/>
      </geometry>
    </visual>
    <collision>
      <origin xyz="-0.0007855109 -0.028511995000000002 -0.03192399" rpy="-0.5594293097385409 -0.02095499521275571 0.006019428316027259"/>
      <geometry>
        <cylinder radius="0.0474698" length="0.07750977987441161"/>
      </geometry>
    </collision>
    <collision>
      <origin xyz="0.000027 -0.049075 -0.064764" rpy="-0.5594293097385409 -0.02095499521275571 0.006019428316027259"/>
      <geometry>
        <sphere radius="0.0474698"/>
      </geometry>
    </collision>
    <collision>
      <origin xyz="-0.001598 -0.007949 0.000916" rpy="-0.5594293097385409 -0.02095499521275571 0.006019428316027259"/>
      <geometry>
        <sphere radius="0.0474698"/>
      </geometry>
    </collision>
  </link>
  <joint name="j_arm1_1" type="revolute">
    <origin xyz="0.0457475 0.169137 0.116626" rpy="0.174533 0.0 -0.5235988"/>
    <axis xyz="0.0 1.0 0.0"/>
    <parent link="torso_2"/>
    <child link="arm1_1"/>
    <limit effort="147.0" lower="-3.312" upper="1.615" velocity="3.86"/>
  </joint>
  <joint name="j_arm1_2" type="revolute">
    <origin xyz="-0.09015 0.062 0.0" rpy="-0.1745327 0.0 0.0"/>
    <axis xyz="1.0 0.0 0.0"/>
    <parent link="arm1_1"/>
    <child link="arm1_2"/>
    <limit effort="147.0" lower="0.02" upper="3.431" velocity="3.86"/>
  </joint>
  <joint name="j_arm1_3" type="revolute">
    <origin xyz="0.09015 0.0 -0.21815" rpy="0 0 0"/>
    <axis xyz="0.0 0.0 1.0"/>
    <parent link="arm1_2"/>
    <child link="arm1_3"/>
    <limit effort="147.0" lower="-2.552" upper="2.566" velocity="6.06"/>
  </joint>
  <joint name="j_arm1_4" type="revolute">
    <origin xyz="0.045 0.05515 -0.074" rpy="0 0 0"/>
    <axis xyz="0.0 1.0 0.0"/>
    <parent link="arm1_3"/>
    <child link="arm1_4"/>
    <limit effort="147.0" lower="-2.465" upper="0.28" velocity="6.06"/>
  </joint>
  <joint name="j_arm1_5" type="revolute">
    <origin xyz="-0.015 -0.05515 -0.095" rpy="0 0 0"/>
    <axis xyz="0.0 0.0 1.0"/>
    <parent link="arm1_4"/>
    <child link="arm1_5"/>
    <limit effort="55.0" lower="-2.569" upper="2.562" velocity="11.72"/>
  </joint>
  <joint name="j_arm1_6" type="revolute">
    <origin xyz="0.0 0.049 -0.156" rpy="0 0 0"/>
    <axis xyz="0.0 1.0 0.0"/>
    <parent link="arm1_5"/>
    <child link="arm1_6"/>
    <limit effort="55.0" lower="-1.529" upper="1.509" velocity="11.72"/>
  </joint>
  <link name="arm2_1">
    <inertial>
      <origin xyz="-0.0074457212 -0.03410796 0.00010978102" rpy="0 0 0"/>
      <mass value="1.9628675"/>
      <inertia ixx="0.0053547717" ixy="-0.00036428926" ixz="1.5089568e-05" iyy="0.0033923328" iyz="-5.5692312e-05" izz="0.0068921413"/>
    </inertial>
    <visual>
      <origin xyz="0.0 0.0 0.0" rpy="0.0 0.0 0.0"/>
      <geometry>
        <mesh filename="package://centauro_urdf/meshes/ShoulderPitch.STL" scale="0.001 0.001 0.001"/>
      </geometry>
      <material name="dark_grey"/>
    </visual>
    <collision>
      <origin xyz="0.017831411999999998 -0.05324115 2.3169000000000008e-05" rpy="1.6903347176271586 1.4526491831510902 1.5721974565036339"/>
      <geometry>
        <cylinder radius="0.0698859" length="0.03739768494560427"/>
      </geometry>
    </collision>
    <collision>
      <origin xyz="-0.000737 -0.051053 0.000286" rpy="1.6903347176271586 1.4526491831510902 1.5721974565036339"/>
      <geometry>
        <sphere radius="0.0698859"/>
      </geometry>
    </collision>
    <collision>
      <origin xyz="0.036400 -0.055429 -0.000240" rpy="1.6903347176271586 1.4526491831510902 1.5721974565036339"/>
      <geometry>
        <sphere radius="0.0698859"/>
      </geometry>
    </collision>
  </link>
  <link name="arm2_2">
    <inertial>
      <origin xyz="0.058142302 -5.7450803e-05 -0.077477683" rpy="0 0 0"/>
      <mass value="1.8595811"/>
      <inertia ixx="0.013776643" ixy="-3.7788675e-05" ixz="0.0037690171" iyy="0.015677464" iyz="9.4893549e-06" izz="0.0046317657"/>
    </inertial>
    <visual>
      <origin xyz="0.0 0.0 0.0" rpy="0.0 0.0 0.0"/>
      <geometry>
        <mesh filename="package://centauro_urdf/meshes/ShoulderRoll.STL" scale="0.001 0.001 0.001"/>
      </geometry>
    </visual>
    <collision>
      <origin xyz="0.0637382 -4.0379999999999995e-07 -0.064359175" rpy="-3.141581408692036 0.43013736369295724 -3.141541177080914"/>
      <geometry>
        <cylinder radius="0.0700645" length="0.12799269981445732"/>
      </geometry>
    </collision>
    <collision>
      <origin xyz="0.037052 -0.000001 -0.006192" rpy="-3.141581408692036 0.43013736369295724 -3.141541177080914"/>
      <geometry>
        <sphere radius="0.0700645"/>
      </geometry>
    </collision>
    <collision>
      <origin xyz="0.090424 0.000000 -0.122526" rpy="-3.141581408692036 0.43013736369295724 -3.141541177080914"/>
      <geometry>
        <sphere radius="0.0700645"/>
      </geometry>
    </collision>
  </link>
  <link name="arm2_3">
    <inertial>
      <origin xyz="0.014625194 -0.0008172672 -0.028333545" rpy="0 0 0"/>
      <mass value="1.6678109"/>
      <inertia ixx="0.0064480435" ixy="0.00015639093" ixz="0.0012205359" iyy="0.0073372077" iyz="-8.9941532e-05" izz="0.0036738448"/>
    </inertial>
    <visual>
      <origin xyz="0.0 0.0 0.0" rpy="0.0 0.0 0.0"/>
      <geometry>
        <mesh filename="package://centauro_urdf/meshes/ShoulderYaw.STL" scale="0.001 0.001 0.001"/>
      </geometry>
      <material name="dark_grey"/>
    </visual>
    <collision>
      <origin xyz="0.0073075385949999995 0.0040911384949999996 -0.03662884" rpy="-3.0024238046134086 0.2429098209130052 -2.103907539504161"/>
      <geometry>
        <cylinder radius="0.0896121" length="0.06082252644344949"/>
      </geometry>
    </collision>
    <collision>
      <origin xyz="-0.000007 -0.000004 -0.007396" rpy="-3.0024238046134086 0.2429098209130052 -2.103907539504161"/>
      <geometry>
        <sphere radius="0.0896121"/>
      </geometry>
    </collision>
    <collision>
      <origin xyz="0.014622 0.008186 -0.065862" rpy="-3.0024238046134086 0.2429098209130052 -2.103907539504161"/>
      <geometry>
        <sphere radius="0.0896121"/>
      </geometry>
    </collision>
  </link>
  <link name="arm2_4">
    <inertial>
      <origin xyz="-0.0076833067 0.040302205 -0.043492779" rpy="0 0 0"/>
      <mass value="1.3157289"/>
      <inertia ixx="0.004330394" ixy="0.00011737391" ixz="-0.00041923199" iyy="0.0038539919" iyz="0.00079573038" izz="0.0017594689"/>
    </inertial>
    <visual>
      <origin xyz="0.0 0.0 0.0" rpy="0.0 0.0 0.0"/>
      <geometry>
        <mesh filename="package://centauro_urdf/meshes/Elbow.STL" scale="0.001 0.001 0.001"/>
      </geometry>
    </visual>
    <collision>
      <origin xyz="-0.00746020465 0.0408499 -0.0404292381" rpy="0.33854605247629793 0.17337814940326016 0.029704070188628324"/>
      <geometry>
        <cylinder radius="0.0600429" length="0.08713418572944408"/>
      </geometry>
    </collision>
    <collision>
      <origin xyz="-0.014976 0.055102 -0.080907" rpy="0.33854605247629793 0.17337814940326016 0.029704070188628324"/>
      <geometry>
        <sphere radius="0.0600429"/>
      </geometry>
    </collision>
    <collision>
      <origin xyz="0.000056 0.026598 0.000049" rpy="0.33854605247629793 0.17337814940326016 0.029704070188628324"/>
      <geometry>
        <sphere radius="0.0600429"/>
      </geometry>
    </collision>
  </link>
  <link name="arm2_5">
    <inertial>
      <origin xyz="-0.00011079615 -0.011590836 -0.07816026" rpy="0 0 0"/>
      <mass value="1.4908547"/>
      <inertia ixx="0.0085692128" ixy="-1.7856252e-05" ixz="1.9379365e-05" iyy="0.0077454159" iyz="0.00032860094" izz="0.0027441921"/>
    </inertial>
    <visual>
      <origin xyz="0.0 0.0 0.0" rpy="0.0 0.0 0.0"/>
      <geometry>
        <mesh filename="package://centauro_urdf/meshes/Forearm.STL" scale="0.001 0.001 0.001"/>
      </geometry>
      <material name="dark_grey"/>
    </visual>
    <collision>
      <origin xyz="-3.7982785e-06 -0.00576208 -0.08227100000000001" rpy="0.1950499967900825 0.00010897079569875528 1.0661198134352675e-05"/>
      <geometry>
        <cylinder radius="0.0804108" length="0.08434739747702645"/>
      </geometry>
    </collision>
    <collision>
      <origin xyz="-0.000008 0.002412 -0.123645" rpy="0.1950499967900825 0.00010897079569875528 1.0661198134352675e-05"/>
      <geometry>
        <sphere radius="0.0804108"/>
      </geometry>
    </collision>
    <collision>
      <origin xyz="0.000001 -0.013936 -0.040897" rpy="0.1950499967900825 0.00010897079569875528 1.0661198134352675e-05"/>
      <geometry>
        <sphere radius="0.0804108"/>
      </geometry>
    </collision>
  </link>
  <link name="arm2_6">
    <inertial>
      <origin xyz="-4.6502396e-06 0.038014094 -0.069926878" rpy="0 0 0"/>
      <mass value="1.1263612"/>
      <inertia ixx="0.0051871784" ixy="-2.724437e-05" ixz="2.2833496e-06" iyy="0.0048037789" iyz="0.00072165653" izz="0.0012771388"/>
    </inertial>
    <visual>
      <origin xyz="0.0 0.0 0.0" rpy="0.0 0.0 0.0"/>
      <geometry>
        <mesh filename="package://centauro_urdf/meshes/wrist_pitch_right.stl" scale="0.001 0.001 0.001"/>
      </geometry>
    </visual>
    <collision>
      <origin xyz="-0.0007855109 0.028511995000000002 -0.03192399" rpy="0.5594293097385409 -0.02095499521275571 -0.006019428316027259"/>
      <geometry>
        <cylinder radius="0.0474698" length="0.07750977987441161"/>
      </geometry>
    </collision>
    <collision>
      <origin xyz="0.000027 0.049075 -0.064764" rpy="0.5594293097385409 -0.02095499521275571 -0.006019428316027259"/>
      <geometry>
        <sphere radius="0.0474698"/>
      </geometry>
    </collision>
    <collision>
      <origin xyz="-0.001598 0.007949 0.000916" rpy="0.5594293097385409 -0.02095499521275571 -0.006019428316027259"/>
      <geometry>
        <sphere radius="0.0474698"/>
      </geometry>
    </collision>
  </link>
  <joint name="j_arm2_1" type="revolute">
    <origin xyz="0.0457475 -0.169137 0.116626" rpy="-0.174533 0.0 0.5235988"/>
    <axis xyz="0.0 1.0 0.0"/>
    <parent link="torso_2"/>
    <child link="arm2_1"/>
    <limit effort="147.0" lower="-3.3458" upper="1.6012" velocity="3.86"/>
  </joint>
  <joint name="j_arm2_2" type="revolute">
    <origin xyz="-0.09015 -0.062 0.0" rpy="0.1745327 0.0 0.0"/>
    <axis xyz="1.0 0.0 0.0"/>
    <parent link="arm2_1"/>
    <child link="arm2_2"/>
    <limit effort="147.0" lower="-3.4258" upper="-0.0138" velocity="3.86"/>
  </joint>
  <joint name="j_arm2_3" type="revolute">
    <origin xyz="0.09015 0.0 -0.21815" rpy="0 0 0"/>
    <axis xyz="0.0 0.0 1.0"/>
    <parent link="arm2_2"/>
    <child link="arm2_3"/>
    <limit effort="147.0" lower="-2.5614" upper="2.5606" velocity="6.06"/>
  </joint>
  <joint name="j_arm2_4" type="revolute">
    <origin xyz="0.045 -0.05515 -0.074" rpy="0 0 0"/>
    <axis xyz="0.0 1.0 0.0"/>
    <parent link="arm2_3"/>
    <child link="arm2_4"/>
    <limit effort="147.0" lower="-2.4794" upper="0.2886" velocity="6.06"/>
  </joint>
  <joint name="j_arm2_5" type="revolute">
    <origin xyz="-0.015 0.05515 -0.095" rpy="0 0 0"/>
    <axis xyz="0.0 0.0 1.0"/>
    <parent link="arm2_4"/>
    <child link="arm2_5"/>
    <limit effort="55.0" lower="-2.5394" upper="2.5546" velocity="11.72"/>
  </joint>
  <joint name="j_arm2_6" type="revolute">
    <origin xyz="0.0 -0.049 -0.156" rpy="0 0 0"/>
    <axis xyz="0.0 1.0 0.0"/>
    <parent link="arm2_5"/>
    <child link="arm2_6"/>
    <limit effort="55.0" lower="-1.5154" upper="1.5156" velocity="11.72"/>
  </joint>
  <link name="ball1">
    <inertial>
      <origin xyz="-1.0072498e-05 3.7590658e-05 0.019772332" rpy="0.0 0.0 0.0"/>
      <mass value="1.27"/>
      <inertia ixx="0.0023061092" ixy="2.9181758e-07" ixz="-2.1246683999999997e-07" iyy="0.0023053155000000002" iyz="7.9290978e-07" izz="0.0030675615999999997"/>
    </inertial>
    <visual>
      <origin xyz="0.0 0.0 0.0" rpy="0.0 0.0 0.0"/>
      <geometry>
        <mesh filename="package://centauro_urdf/meshes/BallHand.stl" scale="0.001 0.001 0.001"/>
      </geometry>
      <material name="dark_grey"/>
    </visual>
    <collision>
      <origin xyz="-2.6819999999999855e-07 1.2015000000000003e-06 -0.0105021" rpy="-1.5654390438571615 -1.1857782102348717 1.1808181135942444"/>
      <geometry>
        <cylinder radius="0.0709883" length="9.940076835940455e-05"/>
      </geometry>
    </collision>
    <collision>
      <origin xyz="0.000046 -0.000017 -0.010502" rpy="-1.5654390438571615 -1.1857782102348717 1.1808181135942444"/>
      <geometry>
        <sphere radius="0.0709883"/>
      </geometry>
    </collision>
    <collision>
      <origin xyz="-0.000046 0.000020 -0.010502" rpy="-1.5654390438571615 -1.1857782102348717 1.1808181135942444"/>
      <geometry>
        <sphere radius="0.0709883"/>
      </geometry>
    </collision>
  </link>
  <link name="ball1_tip"/>
  <joint name="j_arm1_8" type="fixed">
    <origin xyz="0.0 -0.05 -0.105" rpy="0.0 0.0 0.0"/>
    <parent link="arm1_6"/>
    <child link="ball1"/>
  </joint>
  <joint name="j_ball1_tip" type="fixed">
    <origin xyz="0.0 0.0 -0.07" rpy="0.0 0.0 0.0"/>
    <parent link="ball1"/>
    <child link="ball1_tip"/>
  </joint>
  <joint name="j_ball1_fixed" type="fixed">
    <parent link="ball1"/>
    <child link="arm1_8"/>
  </joint>
  <link name="arm1_8">
    <inertial>
      <mass value="0.0"/>
      <inertia ixx="0.0" ixy="0.0" ixz="0.0" iyy="0.0" iyz="0.0" izz="0.0"/>
    </inertial>
  </link>
  <joint name="dagana_2_mount_joint" type="fixed">
    <origin xyz="0.0 0.05 -0.08" rpy="0.0 3.14159265359 3.14159265359"/>
    <parent link="arm2_6"/>
    <child link="dagana_2_top_link"/>
  </joint>
  <link name="dagana_2_top_link">
    <inertial>
      <origin xyz="-0.0063562154 -0.0060265532000000005 0.060068288000000004" rpy="0.0 0.0 0.0"/>
      <mass value="1.74324"/>
      <inertia ixx="0.0050510328" ixy="-0.00025264216" ixz="-0.00012103013" iyy="0.0047944612" iyz="-0.00073917704" izz="0.0031156997"/>
    </inertial>
    <visual>
      <origin xyz="0.0 0.0 0.0" rpy="0.0 0.0 0.0"/>
      <geometry>
        <mesh filename="package://dagana_urdf/meshes/dg0001-simplified.stl" scale="0.001 0.001 0.001"/>
      </geometry>
      <material name="dark_grey"/>
    </visual>
    <collision>
      <origin xyz="-0.000122827 -0.0012617600000000002 0.09111949999999999" rpy="3.0401469956240503 -0.00022380626154906884 -0.004408546116587804"/>
      <geometry>
        <cylinder radius="0.0760764" length="0.10212404260993166"/>
      </geometry>
    </collision>
    <collision>
      <origin xyz="-0.000111 0.003909 0.141919" rpy="3.0401469956240503 -0.00022380626154906884 -0.004408546116587804"/>
      <geometry>
        <sphere radius="0.0760764"/>
      </geometry>
    </collision>
    <collision>
      <origin xyz="-0.000134 -0.006433 0.040320" rpy="3.0401469956240503 -0.00022380626154906884 -0.004408546116587804"/>
      <geometry>
        <sphere radius="0.0760764"/>
      </geometry>
    </collision>
  </link>
  <joint name="dagana_2_claw_joint" type="fixed">
    <origin xyz="0.0 -0.028 0.05025" rpy="1.57079632679 0.0 3.14159265359"/>
    <axis xyz="0.0 0.0 1.0"/>
    <parent link="dagana_2_top_link"/>
    <child link="dagana_2_bottom_link"/>
  </joint>
  <link name="dagana_2_bottom_link">
    <inertial>
      <origin xyz="0.069644767 0.0026548329 -0.041960263" rpy="0.0 0.0 0.0"/>
      <mass value="0.46117745"/>
      <inertia ixx="0.0009385556899999999" ixy="-0.000264452" ixz="7.134683e-05" iyy="0.0019472731" iyz="2.529065e-06" izz="0.0014726990999999999"/>
    </inertial>
    <visual>
      <origin xyz="0.0 0.0 0.0" rpy="0.0 0.0 0.0"/>
      <geometry>
        <mesh filename="package://dagana_urdf/meshes/dg0002.stl" scale="0.001 0.001 0.001"/>
      </geometry>
      <material name="dark_grey"/>
    </visual>
    <collision>
      <origin xyz="-0.000557338 0.06060969 0.00269066" rpy="-1.5078975982532556 -0.0008422964943385845 0.0007909160627971824"/>
      <geometry>
        <cylinder radius="0.0618624" length="0.11781363498578913"/>
      </geometry>
    </collision>
    <collision>
      <origin xyz="-0.000508 0.001819 -0.001012" rpy="-1.5078975982532556 -0.0008422964943385845 0.0007909160627971824"/>
      <geometry>
        <sphere radius="0.0618624"/>
      </geometry>
    </collision>
    <collision>
      <origin xyz="-0.000607 0.119400 0.006393" rpy="-1.5078975982532556 -0.0008422964943385845 0.0007909160627971824"/>
      <geometry>
        <sphere radius="0.0618624"/>
      </geometry>
    </collision>
  </link>
  <joint name="j_arm2_8" type="fixed">
    <parent link="dagana_2_top_link"/>
    <child link="arm2_8"/>
  </joint>
  <link name="arm2_8"/>
  <link name="neck_1">
    <inertial>
      <origin xyz="0.0 0.0 0.0" rpy="0 0 0"/>
      <mass value="0.33878686"/>
      <inertia ixx="0.0003718568" ixy="-9.42983e-05" ixz="-2.80644e-05" iyy="0.0001886879" iyz="-1.54534e-05" izz="0.0005023443"/>
    </inertial>
    <visual>
      <origin xyz="0.0 0.0 0.0" rpy="0.0 0.0 0.0"/>
      <geometry>
        <mesh filename="package://centauro_urdf/meshes/head-base_mesh.stl" scale="0.001 0.001 0.001"/>
      </geometry>
    </visual>
    <collision>
      <origin xyz="0.006498149999999998 -1.4782499999999998e-06 0.1544216" rpy="0.00021616021402232196 0.3728341899733125 4.076931979237498e-05"/>
      <geometry>
        <cylinder radius="0.100414" length="0.16454098025546557"/>
      </geometry>
    </collision>
    <collision>
      <origin xyz="-0.023469 0.000015 0.077803" rpy="0.00021616021402232196 0.3728341899733125 4.076931979237498e-05"/>
      <geometry>
        <sphere radius="0.100414"/>
      </geometry>
    </collision>
    <collision>
      <origin xyz="0.036466 -0.000018 0.231040" rpy="0.00021616021402232196 0.3728341899733125 4.076931979237498e-05"/>
      <geometry>
        <sphere radius="0.100414"/>
      </geometry>
    </collision>
  </link>
  <link name="velodyne_motor">
    <inertial>
      <origin xyz="0.0 0.0 0.0" rpy="0 0 0"/>
      <mass value="0.33878686"/>
      <inertia ixx="0.0003718568" ixy="-9.42983e-05" ixz="-2.80644e-05" iyy="0.0001886879" iyz="-1.54534e-05" izz="0.0005023443"/>
    </inertial>
    <visual>
      <origin xyz="0.0 0.0 0.0" rpy="0.0 0.0 0.0"/>
      <geometry>
        <mesh filename="package://centauro_urdf/meshes/lidar_mesh.stl" scale="0.001 0.001 0.001"/>
      </geometry>
    </visual>
    <collision>
      <origin xyz="-0.0007438725 0.005083050000000001 0.008359974999999999" rpy="-1.5617654568599377 -0.08162793425341344 0.08089487547525437"/>
      <geometry>
        <cylinder radius="0.0544637" length="0.032463112134515464"/>
      </geometry>
    </collision>
    <collision>
      <origin xyz="0.000580 -0.011094 0.008214" rpy="-1.5617654568599377 -0.08162793425341344 0.08089487547525437"/>
      <geometry>
        <sphere radius="0.0544637"/>
      </geometry>
    </collision>
    <collision>
      <origin xyz="-0.002067 0.021260 0.008506" rpy="-1.5617654568599377 -0.08162793425341344 0.08089487547525437"/>
      <geometry>
        <sphere radius="0.0544637"/>
      </geometry>
    </collision>
  </link>
  <link name="d435_head_motor">
    <inertial>
      <origin xyz="0.0 0.0 0.0" rpy="0 0 0"/>
      <mass value="0.33878686"/>
      <inertia ixx="0.0003718568" ixy="-9.42983e-05" ixz="-2.80644e-05" iyy="0.0001886879" iyz="-1.54534e-05" izz="0.0005023443"/>
    </inertial>
    <visual>
      <origin xyz="0.0 0.0 0.0" rpy="0.0 0.0 0.0"/>
      <geometry>
        <mesh filename="package://centauro_urdf/meshes/neck-pitch_mesh.stl" scale="0.001 0.001 0.001"/>
      </geometry>
    </visual>
    <collision>
      <origin xyz="0.01553645 -0.004684799999999996 0.0025092235000000003" rpy="-1.5968195967793293 0.04575443525621143 -0.04696044351276075"/>
      <geometry>
        <cylinder radius="0.0261699" length="0.12134423548428976"/>
      </geometry>
    </collision>
    <collision>
      <origin xyz="0.012761 -0.065273 0.004086" rpy="-1.5968195967793293 0.04575443525621143 -0.04696044351276075"/>
      <geometry>
        <sphere radius="0.0261699"/>
      </geometry>
    </collision>
    <collision>
      <origin xyz="0.018312 0.055903 0.000932" rpy="-1.5968195967793293 0.04575443525621143 -0.04696044351276075"/>
      <geometry>
        <sphere radius="0.0261699"/>
      </geometry>
    </collision>
  </link>
  <joint name="neck_base" type="fixed">
    <origin xyz="0.0030637045 0.0061607221 0.158" rpy="0.0 0.0 0.0"/>
    <axis xyz="0.0 0.0 1.0"/>
    <parent link="torso_2"/>
    <child link="neck_1"/>
  </joint>
  <joint name="velodyne_joint" type="revolute">
    <origin xyz="0.0822724 0.0 0.242" rpy="0.0 0.0 0.0"/>
    <axis xyz="0.0 -1.0 0.0"/>
    <parent link="neck_1"/>
    <child link="velodyne_motor"/>
    <limit effort="35.0" lower="-1.1" upper="1.1" velocity="5.7"/>
    <dynamics friction="10.0"/>
  </joint>
  <joint name="d435_head_joint" type="revolute">
    <origin xyz="0.06 0.0 0.1375" rpy="0.0 0.0 0.0"/>
    <axis xyz="0.0 -1.0 0.0"/>
    <parent link="neck_1"/>
    <child link="d435_head_motor"/>
    <limit effort="35.0" lower="-1.1" upper="1.1" velocity="5.7"/>
    <dynamics friction="10.0"/>
  </joint>
  <joint name="D435_head_camera_joint" type="fixed">
    <origin xyz="0.03015 0.0 -0.0125" rpy="0.0 0.0 0.0"/>
    <parent link="d435_head_motor"/>
    <child link="D435_head_camera_bottom_screw_frame"/>
  </joint>
  <link name="D435_head_camera_bottom_screw_frame"/>
  <joint name="D435_head_camera_link_joint" type="fixed">
    <origin xyz="0.0 0.0175 0.0125" rpy="0.0 0.0 0.0"/>
    <parent link="D435_head_camera_bottom_screw_frame"/>
    <child link="D435_head_camera_link"/>
  </joint>
  <link name="D435_head_camera_link">
    <inertial>
      <origin xyz="0.0 0.0 0.0" rpy="0 0 0"/>
      <mass value="0.564"/>
      <inertia ixx="0.003881243" ixy="0.0" ixz="0.0" iyy="0.00049894" iyz="0.0" izz="0.003879257"/>
    </inertial>
    <visual>
      <origin xyz="0.0149 -0.0175 0.0" rpy="1.570796326795 0.0 1.570796326795"/>
      <geometry>
        <mesh filename="package://centauro_urdf/meshes/realsense/d435.dae"/>
      </geometry>
      <material name="D435_head_camera_aluminum"/>
    </visual>
    <collision>
      <origin xyz="0.0 -0.0175 0.0" rpy="0.0 0.0 0.0"/>
      <geometry>
        <box size="0.02505 0.09 0.025"/>
      </geometry>
    </collision>
  </link>
  <joint name="D435i_camera_joint" type="fixed">
    <origin xyz="0.272 0.0 0.084" rpy="0.0 0.54 0.0"/>
    <parent link="pelvis"/>
    <child link="D435i_camera_bottom_screw_frame"/>
  </joint>
  <link name="D435i_camera_bottom_screw_frame"/>
  <joint name="D435i_camera_link_joint" type="fixed">
    <origin xyz="0.053 0.0 -0.035" rpy="0.0 0.005 -0.008"/>
    <parent link="D435i_camera_bottom_screw_frame"/>
    <child link="D435i_camera_link"/>
  </joint>
  <link name="D435i_camera_link">
    <inertial>
      <origin xyz="0.0 0.0 0.0" rpy="0 0 0"/>
      <mass value="0.564"/>
      <inertia ixx="0.003881243" ixy="0.0" ixz="0.0" iyy="0.00049894" iyz="0.0" izz="0.003879257"/>
    </inertial>
    <visual>
      <origin xyz="0.053 -0.0 0.0" rpy="1.570796326795 0.0 1.570796326795"/>
      <geometry>
        <mesh filename="package://centauro_urdf/meshes/realsense/d435.dae"/>
      </geometry>
      <material name="D435i_camera_aluminum"/>
    </visual>
    <collision>
      <origin xyz="0.0 -0.0 0.0" rpy="0.0 0.0 0.0"/>
      <geometry>
        <box size="0.02505 0.09 0.025"/>
      </geometry>
    </collision>
  </link>
  <link name="hip1_1">
    <inertial>
      <origin xyz="0.0003595855 0.033338818000000006 -0.059190309" rpy="0 0 0"/>
      <mass value="2.3349153"/>
      <inertia ixx="0.0068405374" ixy="1.8572633e-05" ixz="-4.8325972e-05" iyy="0.0026261815" iyz="0.0001564273" izz="0.0066933354"/>
    </inertial>
    <visual>
      <origin xyz="0.0 0.0 0.0" rpy="0.0 0.0 0.0"/>
      <geometry>
        <mesh filename="package://centauro_urdf/meshes/v2/hip-yaw.stl" scale="0.001 -0.001 0.001"/>
      </geometry>
      <material name="dark_grey"/>
    </visual>
    <collision>
      <origin xyz="0.000123454 -0.011949659999999999 -0.0631367" rpy="-1.2794257859148763 0.011059385729693427 -0.008229300412466476"/>
      <geometry>
        <cylinder radius="0.0747223" length="0.03069545889898954"/>
      </geometry>
    </collision>
    <collision>
      <origin xyz="-0.000046 -0.026650 -0.067545" rpy="-1.2794257859148763 0.011059385729693427 -0.008229300412466476"/>
      <geometry>
        <sphere radius="0.0747223"/>
      </geometry>
    </collision>
    <collision>
      <origin xyz="0.000293 0.002750 -0.058728" rpy="-1.2794257859148763 0.011059385729693427 -0.008229300412466476"/>
      <geometry>
        <sphere radius="0.0747223"/>
      </geometry>
    </collision>
  </link>
  <link name="hip2_1">
    <inertial>
      <origin xyz="-4.6285952e-06 -0.2214019 0.03316685" rpy="0 0 0"/>
      <mass value="3.4572118"/>
      <inertia ixx="0.050469853" ixy="-7.784938699999999e-06" ixz="-9.220580999999999e-06" iyy="0.008181596999999999" iyz="0.0059796848" izz="0.048213808999999996"/>
    </inertial>
    <visual>
      <origin xyz="0.0 0.0 0.0" rpy="0.0 0.0 0.0"/>
      <geometry>
        <mesh filename="package://centauro_urdf/meshes/v2/hip-pitch.stl" scale="0.001 0.001 -0.001"/>
      </geometry>
    </visual>
    <collision>
      <origin xyz="1.10696985e-06 -0.13974034 0.0170087" rpy="-1.590922320366177 -7.24562306920002e-06 7.392935812695044e-06"/>
      <geometry>
        <cylinder radius="0.0808941" length="0.2919804521727749"/>
      </geometry>
    </collision>
    <collision>
      <origin xyz="0.000002 -0.285701 0.019947" rpy="-1.590922320366177 -7.24562306920002e-06 7.392935812695044e-06"/>
      <geometry>
        <sphere radius="0.0808941"/>
      </geometry>
    </collision>
    <collision>
      <origin xyz="0.000000 0.006220 0.014071" rpy="-1.590922320366177 -7.24562306920002e-06 7.392935812695044e-06"/>
      <geometry>
        <sphere radius="0.0808941"/>
      </geometry>
    </collision>
  </link>
  <link name="knee_1">
    <inertial>
      <origin xyz="0.00012063381 0.14620674 0.029740711000000003" rpy="0 0 0"/>
      <mass value="2.1199315"/>
      <inertia ixx="0.018426402999999997" ixy="2.8226635999999997e-05" ixz="-2.9204348e-05" iyy="0.0047685615" iyz="-0.002640771" izz="0.017793722"/>
    </inertial>
    <visual>
      <origin xyz="0.0 0.0 0.0" rpy="0.0 0.0 0.0"/>
      <geometry>
        <mesh filename="package://centauro_urdf/meshes/v2/knee.stl" scale="0.001 0.001 -0.001"/>
      </geometry>
      <material name="dark_grey"/>
    </visual>
    <collision>
      <origin xyz="-4.076516e-06 0.0958646315 0.014374499999999998" rpy="-1.6091143483828545 -4.051216032610466e-05 4.20950259773918e-05"/>
      <geometry>
        <cylinder radius="0.0664305" length="0.1927502246061244"/>
      </geometry>
    </collision>
    <collision>
      <origin xyz="-0.000000 -0.000440 0.018066" rpy="-1.6091143483828545 -4.051216032610466e-05 4.20950259773918e-05"/>
      <geometry>
        <sphere radius="0.0664305"/>
      </geometry>
    </collision>
    <collision>
      <origin xyz="-0.000008 0.192169 0.010682" rpy="-1.6091143483828545 -4.051216032610466e-05 4.20950259773918e-05"/>
      <geometry>
        <sphere radius="0.0664305"/>
      </geometry>
    </collision>
  </link>
  <link name="ankle1_1">
    <inertial>
      <origin xyz="0.00012360094 -0.06274712 -0.0049068453" rpy="0 0 0"/>
      <mass value="1.4023368"/>
      <inertia ixx="0.0049928829" ixy="5.762355699999999e-06" ixz="1.9606394e-05" iyy="0.0017621464" iyz="0.00045315091" izz="0.0048706328"/>
    </inertial>
    <visual>
      <origin xyz="0.0 0.0 0.0" rpy="0.0 0.0 0.0"/>
      <geometry>
        <mesh filename="package://centauro_urdf/meshes/v2/ankle-pitch.stl" scale="0.001 0.001 -0.001"/>
      </geometry>
    </visual>
    <collision>
      <origin xyz="-3.39946e-05 -0.0238355765 -1.2084000000000002e-05" rpy="1.5740621233399696 0.0004934392809863637 0.0004950533903306543"/>
      <geometry>
        <cylinder radius="0.0792379" length="0.049256315666076876"/>
      </geometry>
    </collision>
    <collision>
      <origin xyz="-0.000046 0.000792 0.000068" rpy="1.5740621233399696 0.0004934392809863637 0.0004950533903306543"/>
      <geometry>
        <sphere radius="0.0792379"/>
      </geometry>
    </collision>
    <collision>
      <origin xyz="-0.000022 -0.048464 -0.000093" rpy="1.5740621233399696 0.0004934392809863637 0.0004950533903306543"/>
      <geometry>
        <sphere radius="0.0792379"/>
      </geometry>
    </collision>
  </link>
  <link name="ankle2_1">
    <inertial>
      <origin xyz="0.0018496706 -0.00051322371 -0.06730924" rpy="0 0 0"/>
      <mass value="1.7656714"/>
      <inertia ixx="0.0073976286" ixy="9.7557687e-07" ixz="-0.0002295255" iyy="0.0054434358" iyz="3.6337754e-05" izz="0.0043055053"/>
    </inertial>
    <visual>
      <origin xyz="0.0 0.0 0.0" rpy="0.0 0.0 0.0"/>
      <geometry>
        <mesh filename="package://centauro_urdf/meshes/v2/ankle-yaw.stl" scale="0.001 -0.001 0.001"/>
      </geometry>
      <material name="dark_grey"/>
    </visual>
    <collision>
      <origin xyz="-1.177807e-05 -0.001827005 -0.0652808" rpy="3.1390989814835946 0.0002409935691509803 0.1926856017007952"/>
      <geometry>
        <cylinder radius="0.0813545" length="0.07370263129636398"/>
      </geometry>
    </collision>
    <collision>
      <origin xyz="-0.000021 -0.001735 -0.028430" rpy="3.1390989814835946 0.0002409935691509803 0.1926856017007952"/>
      <geometry>
        <sphere radius="0.0813545"/>
      </geometry>
    </collision>
    <collision>
      <origin xyz="-0.000003 -0.001919 -0.102132" rpy="3.1390989814835946 0.0002409935691509803 0.1926856017007952"/>
      <geometry>
        <sphere radius="0.0813545"/>
      </geometry>
    </collision>
  </link>
  <link name="wheel_1">
    <inertial>
      <origin xyz="0.0 0.0 -0.0031155904" rpy="0 0 0"/>
      <mass value="1.11164"/>
      <inertia ixx="0.0028174054" ixy="0.0" ixz="-0.0" iyy="0.0028175648" iyz="-0.0" izz="0.0041817161999999995"/>
    </inertial>
    <visual>
      <origin xyz="0.0 0.0 0.0" rpy="0.0 0.0 0.0"/>
      <geometry>
        <mesh filename="package://centauro_urdf/meshes/v2/wheel.stl" scale="0.001 0.001 -0.001"/>
      </geometry>
      <material name="black"/>
    </visual>
    <collision>
      <origin xyz="0.0 0.0 0.0" rpy="0.0 0.0 0.0"/>
      <geometry>
        <cylinder radius="0.078" length="0.11"/>
      </geometry>
    </collision>
    <collision>
      <origin xyz="0.000000 0.000000 -0.055000" rpy="0.0 0.0 0.0"/>
      <geometry>
        <sphere radius="0.078"/>
      </geometry>
    </collision>
    <collision>
      <origin xyz="0.000000 0.000000 0.055000" rpy="0.0 0.0 0.0"/>
      <geometry>
        <sphere radius="0.078"/>
      </geometry>
    </collision>
  </link>
  <link name="contact_1"/>
  <joint name="contact_joint_1" type="fixed">
    <origin xyz="0.0 0.0 -0.176" rpy="0.0 0.0 0.0"/>
    <parent link="ankle2_1"/>
    <child link="contact_1"/>
  </joint>
  <joint name="hip_yaw_1" type="revolute">
    <origin xyz="0.25 0.125 -0.056600000000000004" rpy="0.0 0.0 0.0"/>
    <axis xyz="0.0 0.0 -1.0"/>
    <parent link="pelvis"/>
    <child link="hip1_1"/>
    <limit effort="304.0" lower="-2.03" upper="2.51" velocity="8.8"/>
  </joint>
  <joint name="hip_pitch_1" type="revolute">
    <origin xyz="0.0 0.1146 -0.0625" rpy="1.57079632679 0.0 0.0"/>
    <axis xyz="0.0 0.0 -1.0"/>
    <parent link="hip1_1"/>
    <child link="hip2_1"/>
    <limit effort="304.0" lower="-2.0226" upper="2.02748" velocity="8.8"/>
  </joint>
  <joint name="knee_pitch_1" type="revolute">
    <origin xyz="0.0 -0.3 0.1182" rpy="3.14159265359 0.0 0.0"/>
    <axis xyz="0.0 0.0 -1.0"/>
    <parent link="hip2_1"/>
    <child link="knee_1"/>
    <limit effort="304.0" lower="-2.4056" upper="2.3994" velocity="8.8"/>
  </joint>
  <joint name="ankle_pitch_1" type="revolute">
    <origin xyz="0.0 0.2 0.10015" rpy="3.14159265359 0.0 0.0"/>
    <axis xyz="0.0 0.0 -1.0"/>
    <parent link="knee_1"/>
    <child link="ankle1_1"/>
    <limit effort="147.0" lower="-2.4056" upper="2.3184" velocity="8.1"/>
  </joint>
  <joint name="ankle_yaw_1" type="revolute">
    <origin xyz="0.0 -0.139 -0.00085" rpy="-1.57079632679 0.0 0.0"/>
    <axis xyz="0.0 0.0 -1.0"/>
    <parent link="ankle1_1"/>
    <child link="ankle2_1"/>
    <limit effort="35.0" lower="-2.5626" upper="2.5384" velocity="20.0"/>
  </joint>
  <joint name="j_wheel_1" type="continuous">
    <origin xyz="0.0 -0.0 -0.09834999999999999" rpy="1.57079632679 0.0 0.0"/>
    <axis xyz="0.0 0.0 -1.0"/>
    <parent link="ankle2_1"/>
    <child link="wheel_1"/>
    <limit effort="35.0" lower="0" upper="0" velocity="20.0"/>
  </joint>
  <link name="hip1_2">
    <inertial>
      <origin xyz="0.0003595855 -0.033338818000000006 -0.059190309" rpy="0 0 0"/>
      <mass value="2.3349153"/>
      <inertia ixx="0.0068405374" ixy="-1.8572633e-05" ixz="-4.8325972e-05" iyy="0.0026261815" iyz="-0.0001564273" izz="0.0066933354"/>
    </inertial>
    <visual>
      <origin xyz="0.0 0.0 0.0" rpy="0.0 0.0 0.0"/>
      <geometry>
        <mesh filename="package://centauro_urdf/meshes/v2/hip-yaw.stl" scale="0.001 0.001 0.001"/>
      </geometry>
      <material name="dark_grey"/>
    </visual>
    <collision>
      <origin xyz="0.000123454 0.011949659999999999 -0.0631367" rpy="1.2794257859148763 0.011059385729693427 0.008229300412466476"/>
      <geometry>
        <cylinder radius="0.0747223" length="0.03069545889898954"/>
      </geometry>
    </collision>
    <collision>
      <origin xyz="-0.000046 0.026650 -0.067545" rpy="1.2794257859148763 0.011059385729693427 0.008229300412466476"/>
      <geometry>
        <sphere radius="0.0747223"/>
      </geometry>
    </collision>
    <collision>
      <origin xyz="0.000293 -0.002750 -0.058728" rpy="1.2794257859148763 0.011059385729693427 0.008229300412466476"/>
      <geometry>
        <sphere radius="0.0747223"/>
      </geometry>
    </collision>
  </link>
  <link name="hip2_2">
    <inertial>
      <origin xyz="-4.6285952e-06 -0.2214019 -0.03316685" rpy="0 0 0"/>
      <mass value="3.4572118"/>
      <inertia ixx="0.050469853" ixy="-7.784938699999999e-06" ixz="9.220580999999999e-06" iyy="0.008181596999999999" iyz="-0.0059796848" izz="0.048213808999999996"/>
    </inertial>
    <visual>
      <origin xyz="0.0 0.0 0.0" rpy="0.0 0.0 0.0"/>
      <geometry>
        <mesh filename="package://centauro_urdf/meshes/v2/hip-pitch.stl" scale="0.001 0.001 0.001"/>
      </geometry>
    </visual>
    <collision>
      <origin xyz="1.10696985e-06 -0.13974034 -0.0170087" rpy="-1.5506703332236162 -7.245623069200021e-06 7.101245701440088e-06"/>
      <geometry>
        <cylinder radius="0.0808941" length="0.2919804521727749"/>
      </geometry>
    </collision>
    <collision>
      <origin xyz="0.000002 -0.285701 -0.019947" rpy="-1.5506703332236162 -7.245623069200021e-06 7.101245701440088e-06"/>
      <geometry>
        <sphere radius="0.0808941"/>
      </geometry>
    </collision>
    <collision>
      <origin xyz="0.000000 0.006220 -0.014071" rpy="-1.5506703332236162 -7.245623069200021e-06 7.101245701440088e-06"/>
      <geometry>
        <sphere radius="0.0808941"/>
      </geometry>
    </collision>
  </link>
  <link name="knee_2">
    <inertial>
      <origin xyz="0.00012063381 0.14620674 -0.029740711000000003" rpy="0 0 0"/>
      <mass value="2.1199315"/>
      <inertia ixx="0.018426402999999997" ixy="2.8226635999999997e-05" ixz="2.9204348e-05" iyy="0.0047685615" iyz="0.002640771" izz="0.017793722"/>
    </inertial>
    <visual>
      <origin xyz="0.0 0.0 0.0" rpy="0.0 0.0 0.0"/>
      <geometry>
        <mesh filename="package://centauro_urdf/meshes/v2/knee.stl" scale="0.001 0.001 0.001"/>
      </geometry>
      <material name="dark_grey"/>
    </visual>
    <collision>
      <origin xyz="-4.076516e-06 0.0958646315 -0.014374499999999998" rpy="-1.5324783052069388 -4.0512160326104654e-05 3.898881390804118e-05"/>
      <geometry>
        <cylinder radius="0.0664305" length="0.1927502246061244"/>
      </geometry>
    </collision>
    <collision>
      <origin xyz="-0.000000 -0.000440 -0.018066" rpy="-1.5324783052069388 -4.0512160326104654e-05 3.898881390804118e-05"/>
      <geometry>
        <sphere radius="0.0664305"/>
      </geometry>
    </collision>
    <collision>
      <origin xyz="-0.000008 0.192169 -0.010683" rpy="-1.5324783052069388 -4.0512160326104654e-05 3.898881390804118e-05"/>
      <geometry>
        <sphere radius="0.0664305"/>
      </geometry>
    </collision>
  </link>
  <link name="ankle1_2">
    <inertial>
      <origin xyz="0.00012360094 -0.06274712 0.0049068453" rpy="0 0 0"/>
      <mass value="1.4023368"/>
      <inertia ixx="0.0049928829" ixy="5.762355699999999e-06" ixz="-1.9606394e-05" iyy="0.0017621464" iyz="-0.00045315091" izz="0.0048706328"/>
    </inertial>
    <visual>
      <origin xyz="0.0 0.0 0.0" rpy="0.0 0.0 0.0"/>
      <geometry>
        <mesh filename="package://centauro_urdf/meshes/v2/ankle-pitch.stl" scale="0.001 0.001 0.001"/>
      </geometry>
    </visual>
    <collision>
      <origin xyz="2.260750000000002e-07 -0.020764664999999998 0.00010889250000000001" rpy="-1.5912124973162882 0.00029736394117794144 -0.00030349780205160657"/>
      <geometry>
        <cylinder radius="0.0781037" length="0.04788405128558378"/>
      </geometry>
    </collision>
    <collision>
      <origin xyz="-0.000007 -0.044702 0.000598" rpy="-1.5912124973162882 0.00029736394117794144 -0.00030349780205160657"/>
      <geometry>
        <sphere radius="0.0781037"/>
      </geometry>
    </collision>
    <collision>
      <origin xyz="0.000007 0.003172 -0.000380" rpy="-1.5912124973162882 0.00029736394117794144 -0.00030349780205160657"/>
      <geometry>
        <sphere radius="0.0781037"/>
      </geometry>
    </collision>
  </link>
  <link name="ankle2_2">
    <inertial>
      <origin xyz="0.0018496706 0.00051322371 -0.06730924" rpy="0 0 0"/>
      <mass value="1.7656714"/>
      <inertia ixx="0.0073976286" ixy="-9.7557687e-07" ixz="-0.0002295255" iyy="0.0054434358" iyz="-3.6337754e-05" izz="0.0043055053"/>
    </inertial>
    <visual>
      <origin xyz="0.0 0.0 0.0" rpy="0.0 0.0 0.0"/>
      <geometry>
        <mesh filename="package://centauro_urdf/meshes/v2/ankle-yaw.stl" scale="0.001 0.001 0.001"/>
      </geometry>
      <material name="dark_grey"/>
    </visual>
    <collision>
      <origin xyz="-1.177807e-05 0.001827005 -0.0652808" rpy="-3.1390989814835946 0.0002409935691509803 -0.1926856017007952"/>
      <geometry>
        <cylinder radius="0.0813545" length="0.07370263129636398"/>
      </geometry>
    </collision>
    <collision>
      <origin xyz="-0.000021 0.001735 -0.028430" rpy="-3.1390989814835946 0.0002409935691509803 -0.1926856017007952"/>
      <geometry>
        <sphere radius="0.0813545"/>
      </geometry>
    </collision>
    <collision>
      <origin xyz="-0.000003 0.001919 -0.102132" rpy="-3.1390989814835946 0.0002409935691509803 -0.1926856017007952"/>
      <geometry>
        <sphere radius="0.0813545"/>
      </geometry>
    </collision>
  </link>
  <link name="wheel_2">
    <inertial>
      <origin xyz="0.0 0.0 0.0031155904" rpy="0 0 0"/>
      <mass value="1.11164"/>
      <inertia ixx="0.0028174054" ixy="0.0" ixz="0.0" iyy="0.0028175648" iyz="0.0" izz="0.0041817161999999995"/>
    </inertial>
    <visual>
      <origin xyz="0.0 0.0 0.0" rpy="0.0 0.0 0.0"/>
      <geometry>
        <mesh filename="package://centauro_urdf/meshes/v2/wheel.stl" scale="0.001 0.001 0.001"/>
      </geometry>
      <material name="black"/>
    </visual>
    <collision>
      <origin xyz="0.0 0.0 0.0" rpy="0.0 0.0 0.0"/>
      <geometry>
        <cylinder radius="0.078" length="0.11"/>
      </geometry>
    </collision>
    <collision>
      <origin xyz="0.000000 0.000000 -0.055000" rpy="0.0 0.0 0.0"/>
      <geometry>
        <sphere radius="0.078"/>
      </geometry>
    </collision>
    <collision>
      <origin xyz="0.000000 0.000000 0.055000" rpy="0.0 0.0 0.0"/>
      <geometry>
        <sphere radius="0.078"/>
      </geometry>
    </collision>
  </link>
  <link name="contact_2"/>
  <joint name="contact_joint_2" type="fixed">
    <origin xyz="0.0 0.0 -0.176" rpy="0.0 0.0 0.0"/>
    <parent link="ankle2_2"/>
    <child link="contact_2"/>
  </joint>
  <joint name="hip_yaw_2" type="revolute">
    <origin xyz="0.25 -0.125 -0.056600000000000004" rpy="0.0 0.0 0.0"/>
    <axis xyz="0.0 0.0 -1.0"/>
    <parent link="pelvis"/>
    <child link="hip1_2"/>
    <limit effort="304.0" lower="-2.51" upper="2.03" velocity="8.8"/>
  </joint>
  <joint name="hip_pitch_2" type="revolute">
    <origin xyz="0.0 -0.1146 -0.0625" rpy="1.57079632679 0.0 0.0"/>
    <axis xyz="0.0 0.0 1.0"/>
    <parent link="hip1_2"/>
    <child link="hip2_2"/>
    <limit effort="304.0" lower="-2.0156" upper="2.0354" velocity="8.8"/>
  </joint>
  <joint name="knee_pitch_2" type="revolute">
    <origin xyz="0.0 -0.3 -0.1182" rpy="3.14159265359 0.0 0.0"/>
    <axis xyz="0.0 0.0 1.0"/>
    <parent link="hip2_2"/>
    <child link="knee_2"/>
    <limit effort="304.0" lower="-2.4006" upper="2.4034" velocity="8.8"/>
  </joint>
  <joint name="ankle_pitch_2" type="revolute">
    <origin xyz="0.0 0.2 -0.10015" rpy="3.14159265359 0.0 0.0"/>
    <axis xyz="0.0 0.0 1.0"/>
    <parent link="knee_2"/>
    <child link="ankle1_2"/>
    <limit effort="147.0" lower="-2.3266" upper="2.3914" velocity="8.1"/>
  </joint>
  <joint name="ankle_yaw_2" type="revolute">
    <origin xyz="0.0 -0.139 0.00085" rpy="-1.57079632679 0.0 0.0"/>
    <axis xyz="0.0 0.0 -1.0"/>
    <parent link="ankle1_2"/>
    <child link="ankle2_2"/>
    <limit effort="35.0" lower="-2.5546" upper="2.5484" velocity="20.0"/>
  </joint>
  <joint name="j_wheel_2" type="continuous">
    <origin xyz="0.0 0.0 -0.09834999999999999" rpy="1.57079632679 0.0 0.0"/>
    <axis xyz="0.0 0.0 1.0"/>
    <parent link="ankle2_2"/>
    <child link="wheel_2"/>
    <limit effort="35.0" lower="0" upper="0" velocity="20.0"/>
  </joint>
  <link name="hip1_3">
    <inertial>
      <origin xyz="0.0003595855 0.033338818000000006 -0.059190309" rpy="0 0 0"/>
      <mass value="2.3349153"/>
      <inertia ixx="0.0068405374" ixy="1.8572633e-05" ixz="-4.8325972e-05" iyy="0.0026261815" iyz="0.0001564273" izz="0.0066933354"/>
    </inertial>
    <visual>
      <origin xyz="0.0 0.0 0.0" rpy="0.0 0.0 0.0"/>
      <geometry>
        <mesh filename="package://centauro_urdf/meshes/v2/hip-yaw.stl" scale="0.001 -0.001 0.001"/>
      </geometry>
      <material name="dark_grey"/>
    </visual>
    <collision>
      <origin xyz="0.000123454 -0.011949659999999999 -0.0631367" rpy="-1.2794257859148763 0.011059385729693427 -0.008229300412466476"/>
      <geometry>
        <cylinder radius="0.0747223" length="0.03069545889898954"/>
      </geometry>
    </collision>
    <collision>
      <origin xyz="-0.000046 -0.026650 -0.067545" rpy="-1.2794257859148763 0.011059385729693427 -0.008229300412466476"/>
      <geometry>
        <sphere radius="0.0747223"/>
      </geometry>
    </collision>
    <collision>
      <origin xyz="0.000293 0.002750 -0.058728" rpy="-1.2794257859148763 0.011059385729693427 -0.008229300412466476"/>
      <geometry>
        <sphere radius="0.0747223"/>
      </geometry>
    </collision>
  </link>
  <link name="hip2_3">
    <inertial>
      <origin xyz="-4.6285952e-06 -0.2214019 0.03316685" rpy="0 0 0"/>
      <mass value="3.4572118"/>
      <inertia ixx="0.050469853" ixy="-7.784938699999999e-06" ixz="-9.220580999999999e-06" iyy="0.008181596999999999" iyz="0.0059796848" izz="0.048213808999999996"/>
    </inertial>
    <visual>
      <origin xyz="0.0 0.0 0.0" rpy="0.0 0.0 0.0"/>
      <geometry>
        <mesh filename="package://centauro_urdf/meshes/v2/hip-pitch.stl" scale="0.001 0.001 -0.001"/>
      </geometry>
    </visual>
    <collision>
      <origin xyz="1.10696985e-06 -0.13974034 0.0170087" rpy="-1.590922320366177 -7.24562306920002e-06 7.392935812695044e-06"/>
      <geometry>
        <cylinder radius="0.0808941" length="0.2919804521727749"/>
      </geometry>
    </collision>
    <collision>
      <origin xyz="0.000002 -0.285701 0.019947" rpy="-1.590922320366177 -7.24562306920002e-06 7.392935812695044e-06"/>
      <geometry>
        <sphere radius="0.0808941"/>
      </geometry>
    </collision>
    <collision>
      <origin xyz="0.000000 0.006220 0.014071" rpy="-1.590922320366177 -7.24562306920002e-06 7.392935812695044e-06"/>
      <geometry>
        <sphere radius="0.0808941"/>
      </geometry>
    </collision>
  </link>
  <link name="knee_3">
    <inertial>
      <origin xyz="0.00012063381 0.14620674 0.029740711000000003" rpy="0 0 0"/>
      <mass value="2.1199315"/>
      <inertia ixx="0.018426402999999997" ixy="2.8226635999999997e-05" ixz="-2.9204348e-05" iyy="0.0047685615" iyz="-0.002640771" izz="0.017793722"/>
    </inertial>
    <visual>
      <origin xyz="0.0 0.0 0.0" rpy="0.0 0.0 0.0"/>
      <geometry>
        <mesh filename="package://centauro_urdf/meshes/v2/knee.stl" scale="0.001 0.001 -0.001"/>
      </geometry>
      <material name="dark_grey"/>
    </visual>
    <collision>
      <origin xyz="-4.076516e-06 0.0958646315 0.014374499999999998" rpy="-1.6091143483828545 -4.051216032610466e-05 4.20950259773918e-05"/>
      <geometry>
        <cylinder radius="0.0664305" length="0.1927502246061244"/>
      </geometry>
    </collision>
    <collision>
      <origin xyz="-0.000000 -0.000440 0.018066" rpy="-1.6091143483828545 -4.051216032610466e-05 4.20950259773918e-05"/>
      <geometry>
        <sphere radius="0.0664305"/>
      </geometry>
    </collision>
    <collision>
      <origin xyz="-0.000008 0.192169 0.010682" rpy="-1.6091143483828545 -4.051216032610466e-05 4.20950259773918e-05"/>
      <geometry>
        <sphere radius="0.0664305"/>
      </geometry>
    </collision>
  </link>
  <link name="ankle1_3">
    <inertial>
      <origin xyz="0.00012360094 -0.06274712 -0.0049068453" rpy="0 0 0"/>
      <mass value="1.4023368"/>
      <inertia ixx="0.0049928829" ixy="5.762355699999999e-06" ixz="1.9606394e-05" iyy="0.0017621464" iyz="0.00045315091" izz="0.0048706328"/>
    </inertial>
    <visual>
      <origin xyz="0.0 0.0 0.0" rpy="0.0 0.0 0.0"/>
      <geometry>
        <mesh filename="package://centauro_urdf/meshes/v2/ankle-pitch.stl" scale="0.001 0.001 -0.001"/>
      </geometry>
    </visual>
    <collision>
      <origin xyz="-3.39946e-05 -0.0238355765 -1.2084000000000002e-05" rpy="1.5740621233399696 0.0004934392809863637 0.0004950533903306543"/>
      <geometry>
        <cylinder radius="0.0792379" length="0.049256315666076876"/>
      </geometry>
    </collision>
    <collision>
      <origin xyz="-0.000046 0.000792 0.000068" rpy="1.5740621233399696 0.0004934392809863637 0.0004950533903306543"/>
      <geometry>
        <sphere radius="0.0792379"/>
      </geometry>
    </collision>
    <collision>
      <origin xyz="-0.000022 -0.048464 -0.000093" rpy="1.5740621233399696 0.0004934392809863637 0.0004950533903306543"/>
      <geometry>
        <sphere radius="0.0792379"/>
      </geometry>
    </collision>
  </link>
  <link name="ankle2_3">
    <inertial>
      <origin xyz="0.0018496706 -0.00051322371 -0.06730924" rpy="0 0 0"/>
      <mass value="1.7656714"/>
      <inertia ixx="0.0073976286" ixy="9.7557687e-07" ixz="-0.0002295255" iyy="0.0054434358" iyz="3.6337754e-05" izz="0.0043055053"/>
    </inertial>
    <visual>
      <origin xyz="0.0 0.0 0.0" rpy="0.0 0.0 0.0"/>
      <geometry>
        <mesh filename="package://centauro_urdf/meshes/v2/ankle-yaw.stl" scale="0.001 -0.001 0.001"/>
      </geometry>
      <material name="dark_grey"/>
    </visual>
    <collision>
      <origin xyz="-1.177807e-05 -0.001827005 -0.0652808" rpy="3.1390989814835946 0.0002409935691509803 0.1926856017007952"/>
      <geometry>
        <cylinder radius="0.0813545" length="0.07370263129636398"/>
      </geometry>
    </collision>
    <collision>
      <origin xyz="-0.000021 -0.001735 -0.028430" rpy="3.1390989814835946 0.0002409935691509803 0.1926856017007952"/>
      <geometry>
        <sphere radius="0.0813545"/>
      </geometry>
    </collision>
    <collision>
      <origin xyz="-0.000003 -0.001919 -0.102132" rpy="3.1390989814835946 0.0002409935691509803 0.1926856017007952"/>
      <geometry>
        <sphere radius="0.0813545"/>
      </geometry>
    </collision>
  </link>
  <link name="wheel_3">
    <inertial>
      <origin xyz="0.0 0.0 -0.0031155904" rpy="0 0 0"/>
      <mass value="1.11164"/>
      <inertia ixx="0.0028174054" ixy="0.0" ixz="-0.0" iyy="0.0028175648" iyz="-0.0" izz="0.0041817161999999995"/>
    </inertial>
    <visual>
      <origin xyz="0.0 0.0 0.0" rpy="0.0 0.0 0.0"/>
      <geometry>
        <mesh filename="package://centauro_urdf/meshes/v2/wheel.stl" scale="0.001 0.001 -0.001"/>
      </geometry>
      <material name="black"/>
    </visual>
    <collision>
      <origin xyz="0.0 0.0 0.0" rpy="0.0 0.0 0.0"/>
      <geometry>
        <cylinder radius="0.078" length="0.11"/>
      </geometry>
    </collision>
    <collision>
      <origin xyz="0.000000 0.000000 -0.055000" rpy="0.0 0.0 0.0"/>
      <geometry>
        <sphere radius="0.078"/>
      </geometry>
    </collision>
    <collision>
      <origin xyz="0.000000 0.000000 0.055000" rpy="0.0 0.0 0.0"/>
      <geometry>
        <sphere radius="0.078"/>
      </geometry>
    </collision>
  </link>
  <link name="contact_3"/>
  <joint name="contact_joint_3" type="fixed">
    <origin xyz="0.0 0.0 -0.176" rpy="0.0 0.0 0.0"/>
    <parent link="ankle2_3"/>
    <child link="contact_3"/>
  </joint>
  <joint name="hip_yaw_3" type="revolute">
    <origin xyz="-0.25 0.125 -0.056600000000000004" rpy="0.0 0.0 0.0"/>
    <axis xyz="0.0 0.0 -1.0"/>
    <parent link="pelvis"/>
    <child link="hip1_3"/>
    <limit effort="304.0" lower="-2.51" upper="2.03" velocity="8.8"/>
  </joint>
  <joint name="hip_pitch_3" type="revolute">
    <origin xyz="0.0 0.1146 -0.0625" rpy="1.57079632679 0.0 0.0"/>
    <axis xyz="0.0 0.0 -1.0"/>
    <parent link="hip1_3"/>
    <child link="hip2_3"/>
    <limit effort="304.0" lower="-2.0126" upper="2.0384" velocity="8.8"/>
  </joint>
  <joint name="knee_pitch_3" type="revolute">
    <origin xyz="0.0 -0.3 0.1182" rpy="3.14159265359 0.0 0.0"/>
    <axis xyz="0.0 0.0 -1.0"/>
    <parent link="hip2_3"/>
    <child link="knee_3"/>
    <limit effort="304.0" lower="-2.4056" upper="2.4064" velocity="8.8"/>
  </joint>
  <joint name="ankle_pitch_3" type="revolute">
    <origin xyz="0.0 0.2 0.10015" rpy="3.14159265359 0.0 0.0"/>
    <axis xyz="0.0 0.0 -1.0"/>
    <parent link="knee_3"/>
    <child link="ankle1_3"/>
    <limit effort="147.0" lower="-2.4696" upper="2.4464" velocity="8.1"/>
  </joint>
  <joint name="ankle_yaw_3" type="revolute">
    <origin xyz="0.0 -0.139 -0.00085" rpy="-1.57079632679 0.0 0.0"/>
    <axis xyz="0.0 0.0 -1.0"/>
    <parent link="ankle1_3"/>
    <child link="ankle2_3"/>
    <limit effort="35.0" lower="-2.5606" upper="2.5454" velocity="20.0"/>
  </joint>
  <joint name="j_wheel_3" type="continuous">
    <origin xyz="0.0 -0.0 -0.09834999999999999" rpy="1.57079632679 0.0 0.0"/>
    <axis xyz="0.0 0.0 -1.0"/>
    <parent link="ankle2_3"/>
    <child link="wheel_3"/>
    <limit effort="35.0" lower="0" upper="0" velocity="20.0"/>
  </joint>
  <link name="hip1_4">
    <inertial>
      <origin xyz="0.0003595855 -0.033338818000000006 -0.059190309" rpy="0 0 0"/>
      <mass value="2.3349153"/>
      <inertia ixx="0.0068405374" ixy="-1.8572633e-05" ixz="-4.8325972e-05" iyy="0.0026261815" iyz="-0.0001564273" izz="0.0066933354"/>
    </inertial>
    <visual>
      <origin xyz="0.0 0.0 0.0" rpy="0.0 0.0 0.0"/>
      <geometry>
        <mesh filename="package://centauro_urdf/meshes/v2/hip-yaw.stl" scale="0.001 0.001 0.001"/>
      </geometry>
      <material name="dark_grey"/>
    </visual>
    <collision>
      <origin xyz="0.000123454 0.011949659999999999 -0.0631367" rpy="1.2794257859148763 0.011059385729693427 0.008229300412466476"/>
      <geometry>
        <cylinder radius="0.0747223" length="0.03069545889898954"/>
      </geometry>
    </collision>
    <collision>
      <origin xyz="-0.000046 0.026650 -0.067545" rpy="1.2794257859148763 0.011059385729693427 0.008229300412466476"/>
      <geometry>
        <sphere radius="0.0747223"/>
      </geometry>
    </collision>
    <collision>
      <origin xyz="0.000293 -0.002750 -0.058728" rpy="1.2794257859148763 0.011059385729693427 0.008229300412466476"/>
      <geometry>
        <sphere radius="0.0747223"/>
      </geometry>
    </collision>
  </link>
  <link name="hip2_4">
    <inertial>
      <origin xyz="-4.6285952e-06 -0.2214019 -0.03316685" rpy="0 0 0"/>
      <mass value="3.4572118"/>
      <inertia ixx="0.050469853" ixy="-7.784938699999999e-06" ixz="9.220580999999999e-06" iyy="0.008181596999999999" iyz="-0.0059796848" izz="0.048213808999999996"/>
    </inertial>
    <visual>
      <origin xyz="0.0 0.0 0.0" rpy="0.0 0.0 0.0"/>
      <geometry>
        <mesh filename="package://centauro_urdf/meshes/v2/hip-pitch.stl" scale="0.001 0.001 0.001"/>
      </geometry>
    </visual>
    <collision>
      <origin xyz="1.10696985e-06 -0.13974034 -0.0170087" rpy="-1.5506703332236162 -7.245623069200021e-06 7.101245701440088e-06"/>
      <geometry>
        <cylinder radius="0.0808941" length="0.2919804521727749"/>
      </geometry>
    </collision>
    <collision>
      <origin xyz="0.000002 -0.285701 -0.019947" rpy="-1.5506703332236162 -7.245623069200021e-06 7.101245701440088e-06"/>
      <geometry>
        <sphere radius="0.0808941"/>
      </geometry>
    </collision>
    <collision>
      <origin xyz="0.000000 0.006220 -0.014071" rpy="-1.5506703332236162 -7.245623069200021e-06 7.101245701440088e-06"/>
      <geometry>
        <sphere radius="0.0808941"/>
      </geometry>
    </collision>
  </link>
  <link name="knee_4">
    <inertial>
      <origin xyz="0.00012063381 0.14620674 -0.029740711000000003" rpy="0 0 0"/>
      <mass value="2.1199315"/>
      <inertia ixx="0.018426402999999997" ixy="2.8226635999999997e-05" ixz="2.9204348e-05" iyy="0.0047685615" iyz="0.002640771" izz="0.017793722"/>
    </inertial>
    <visual>
      <origin xyz="0.0 0.0 0.0" rpy="0.0 0.0 0.0"/>
      <geometry>
        <mesh filename="package://centauro_urdf/meshes/v2/knee.stl" scale="0.001 0.001 0.001"/>
      </geometry>
      <material name="dark_grey"/>
    </visual>
    <collision>
      <origin xyz="-4.076516e-06 0.0958646315 -0.014374499999999998" rpy="-1.5324783052069388 -4.0512160326104654e-05 3.898881390804118e-05"/>
      <geometry>
        <cylinder radius="0.0664305" length="0.1927502246061244"/>
      </geometry>
    </collision>
    <collision>
      <origin xyz="-0.000000 -0.000440 -0.018066" rpy="-1.5324783052069388 -4.0512160326104654e-05 3.898881390804118e-05"/>
      <geometry>
        <sphere radius="0.0664305"/>
      </geometry>
    </collision>
    <collision>
      <origin xyz="-0.000008 0.192169 -0.010683" rpy="-1.5324783052069388 -4.0512160326104654e-05 3.898881390804118e-05"/>
      <geometry>
        <sphere radius="0.0664305"/>
      </geometry>
    </collision>
  </link>
  <link name="ankle1_4">
    <inertial>
      <origin xyz="0.00012360094 -0.06274712 0.0049068453" rpy="0 0 0"/>
      <mass value="1.4023368"/>
      <inertia ixx="0.0049928829" ixy="5.762355699999999e-06" ixz="-1.9606394e-05" iyy="0.0017621464" iyz="-0.00045315091" izz="0.0048706328"/>
    </inertial>
    <visual>
      <origin xyz="0.0 0.0 0.0" rpy="0.0 0.0 0.0"/>
      <geometry>
        <mesh filename="package://centauro_urdf/meshes/v2/ankle-pitch.stl" scale="0.001 0.001 0.001"/>
      </geometry>
    </visual>
    <collision>
      <origin xyz="2.260750000000002e-07 -0.020764664999999998 0.00010889250000000001" rpy="-1.5912124973162882 0.00029736394117794144 -0.00030349780205160657"/>
      <geometry>
        <cylinder radius="0.0781037" length="0.04788405128558378"/>
      </geometry>
    </collision>
    <collision>
      <origin xyz="-0.000007 -0.044702 0.000598" rpy="-1.5912124973162882 0.00029736394117794144 -0.00030349780205160657"/>
      <geometry>
        <sphere radius="0.0781037"/>
      </geometry>
    </collision>
    <collision>
      <origin xyz="0.000007 0.003172 -0.000380" rpy="-1.5912124973162882 0.00029736394117794144 -0.00030349780205160657"/>
      <geometry>
        <sphere radius="0.0781037"/>
      </geometry>
    </collision>
  </link>
  <link name="ankle2_4">
    <inertial>
      <origin xyz="0.0018496706 0.00051322371 -0.06730924" rpy="0 0 0"/>
      <mass value="1.7656714"/>
      <inertia ixx="0.0073976286" ixy="-9.7557687e-07" ixz="-0.0002295255" iyy="0.0054434358" iyz="-3.6337754e-05" izz="0.0043055053"/>
    </inertial>
    <visual>
      <origin xyz="0.0 0.0 0.0" rpy="0.0 0.0 0.0"/>
      <geometry>
        <mesh filename="package://centauro_urdf/meshes/v2/ankle-yaw.stl" scale="0.001 0.001 0.001"/>
      </geometry>
      <material name="dark_grey"/>
    </visual>
    <collision>
      <origin xyz="-1.177807e-05 0.001827005 -0.0652808" rpy="-3.1390989814835946 0.0002409935691509803 -0.1926856017007952"/>
      <geometry>
        <cylinder radius="0.0813545" length="0.07370263129636398"/>
      </geometry>
    </collision>
    <collision>
      <origin xyz="-0.000021 0.001735 -0.028430" rpy="-3.1390989814835946 0.0002409935691509803 -0.1926856017007952"/>
      <geometry>
        <sphere radius="0.0813545"/>
      </geometry>
    </collision>
    <collision>
      <origin xyz="-0.000003 0.001919 -0.102132" rpy="-3.1390989814835946 0.0002409935691509803 -0.1926856017007952"/>
      <geometry>
        <sphere radius="0.0813545"/>
      </geometry>
    </collision>
  </link>
  <link name="wheel_4">
    <inertial>
      <origin xyz="0.0 0.0 0.0031155904" rpy="0 0 0"/>
      <mass value="1.11164"/>
      <inertia ixx="0.0028174054" ixy="0.0" ixz="0.0" iyy="0.0028175648" iyz="0.0" izz="0.0041817161999999995"/>
    </inertial>
    <visual>
      <origin xyz="0.0 0.0 0.0" rpy="0.0 0.0 0.0"/>
      <geometry>
        <mesh filename="package://centauro_urdf/meshes/v2/wheel.stl" scale="0.001 0.001 0.001"/>
      </geometry>
      <material name="black"/>
    </visual>
    <collision>
      <origin xyz="0.0 0.0 0.0" rpy="0.0 0.0 0.0"/>
      <geometry>
        <cylinder radius="0.078" length="0.11"/>
      </geometry>
    </collision>
    <collision>
      <origin xyz="0.000000 0.000000 -0.055000" rpy="0.0 0.0 0.0"/>
      <geometry>
        <sphere radius="0.078"/>
      </geometry>
    </collision>
    <collision>
      <origin xyz="0.000000 0.000000 0.055000" rpy="0.0 0.0 0.0"/>
      <geometry>
        <sphere radius="0.078"/>
      </geometry>
    </collision>
  </link>
  <link name="contact_4"/>
  <joint name="contact_joint_4" type="fixed">
    <origin xyz="0.0 0.0 -0.176" rpy="0.0 0.0 0.0"/>
    <parent link="ankle2_4"/>
    <child link="contact_4"/>
  </joint>
  <joint name="hip_yaw_4" type="revolute">
    <origin xyz="-0.25 -0.125 -0.056600000000000004" rpy="0.0 0.0 0.0"/>
    <axis xyz="0.0 0.0 -1.0"/>
    <parent link="pelvis"/>
    <child link="hip1_4"/>
    <limit effort="304.0" lower="-2.03" upper="2.51" velocity="8.8"/>
  </joint>
  <joint name="hip_pitch_4" type="revolute">
    <origin xyz="0.0 -0.1146 -0.0625" rpy="1.57079632679 0.0 0.0"/>
    <axis xyz="0.0 0.0 1.0"/>
    <parent link="hip1_4"/>
    <child link="hip2_4"/>
    <limit effort="304.0" lower="-2.0326" upper="2.0524" velocity="8.8"/>
  </joint>
  <joint name="knee_pitch_4" type="revolute">
    <origin xyz="0.0 -0.3 -0.1182" rpy="3.14159265359 0.0 0.0"/>
    <axis xyz="0.0 0.0 1.0"/>
    <parent link="hip2_4"/>
    <child link="knee_4"/>
    <limit effort="304.0" lower="-2.4176" upper="2.3884" velocity="8.8"/>
  </joint>
  <joint name="ankle_pitch_4" type="revolute">
    <origin xyz="0.0 0.2 -0.10015" rpy="3.14159265359 0.0 0.0"/>
    <axis xyz="0.0 0.0 1.0"/>
    <parent link="knee_4"/>
    <child link="ankle1_4"/>
    <limit effort="147.0" lower="-2.3426" upper="2.3934" velocity="8.1"/>
  </joint>
  <joint name="ankle_yaw_4" type="revolute">
    <origin xyz="0.0 -0.139 0.00085" rpy="-1.57079632679 0.0 0.0"/>
    <axis xyz="0.0 0.0 -1.0"/>
    <parent link="ankle1_4"/>
    <child link="ankle2_4"/>
    <limit effort="35.0" lower="-2.6046" upper="2.5514" velocity="20.0"/>
  </joint>
  <joint name="j_wheel_4" type="continuous">
    <origin xyz="0.0 0.0 -0.09834999999999999" rpy="1.57079632679 0.0 0.0"/>
    <axis xyz="0.0 0.0 1.0"/>
    <parent link="ankle2_4"/>
    <child link="wheel_4"/>
    <limit effort="35.0" lower="0" upper="0" velocity="20.0"/>
  </joint>
  <link name="world"/>
  <joint name="reference" type="floating">
    <parent link="world"/>
    <child link="pelvis"/>
  </joint>
  <joint name="car_frame_tx" type="prismatic">
    <origin xyz="0.0 0.0 0.0" rpy="0 0 0"/>
    <axis xyz="1.0 0.0 0.0"/>
    <parent link="pelvis"/>
    <child link="car_frame_intermediate_1"/>
    <limit effort="1000.0" lower="-1000000000.0" upper="1000000000.0" velocity="10.0"/>
  </joint>
  <link name="car_frame_intermediate_1">
    <inertial>
      <mass value="0.0"/>
      <inertia ixx="0.0" ixy="0.0" ixz="0.0" iyy="0.0" iyz="0.0" izz="0.0"/>
    </inertial>
  </link>
  <joint name="car_frame_ty" type="prismatic">
    <origin xyz="0.0 0.0 0.0" rpy="0 0 0"/>
    <axis xyz="0.0 1.0 0.0"/>
    <parent link="car_frame_intermediate_1"/>
    <child link="car_frame_intermediate_2"/>
    <limit effort="1000.0" lower="-1000000000.0" upper="1000000000.0" velocity="10.0"/>
  </joint>
  <link name="car_frame_intermediate_2">
    <inertial>
      <mass value="0.0"/>
      <inertia ixx="0.0" ixy="0.0" ixz="0.0" iyy="0.0" iyz="0.0" izz="0.0"/>
    </inertial>
  </link>
  <joint name="car_frame_tz" type="prismatic">
    <origin xyz="0.0 0.0 0.0" rpy="0 0 0"/>
    <axis xyz="0.0 0.0 1.0"/>
    <parent link="car_frame_intermediate_2"/>
    <child link="car_frame_intermediate_3"/>
    <limit effort="1000.0" lower="-1000000000.0" upper="1000000000.0" velocity="10.0"/>
  </joint>
  <link name="car_frame_intermediate_3">
    <inertial>
      <mass value="0.0"/>
      <inertia ixx="0.0" ixy="0.0" ixz="0.0" iyy="0.0" iyz="0.0" izz="0.0"/>
    </inertial>
  </link>
  <joint name="car_frame_rx" type="revolute">
    <origin xyz="0.0 0.0 0.0" rpy="0 0 0"/>
    <axis xyz="1.0 0.0 0.0"/>
    <parent link="car_frame_intermediate_3"/>
    <child link="car_frame_intermediate_4"/>
    <limit effort="1000.0" lower="-1000000000.0" upper="1000000000.0" velocity="10.0"/>
  </joint>
  <link name="car_frame_intermediate_4">
    <inertial>
      <mass value="0.0"/>
      <inertia ixx="0.0" ixy="0.0" ixz="0.0" iyy="0.0" iyz="0.0" izz="0.0"/>
    </inertial>
  </link>
  <joint name="car_frame_ry" type="revolute">
    <origin xyz="0.0 0.0 0.0" rpy="0 0 0"/>
    <axis xyz="0.0 1.0 0.0"/>
    <parent link="car_frame_intermediate_4"/>
    <child link="car_frame_intermediate_5"/>
    <limit effort="1000.0" lower="-1000000000.0" upper="1000000000.0" velocity="10.0"/>
  </joint>
  <link name="car_frame_intermediate_5">
    <inertial>
      <mass value="0.0"/>
      <inertia ixx="0.0" ixy="0.0" ixz="0.0" iyy="0.0" iyz="0.0" izz="0.0"/>
    </inertial>
  </link>
  <joint name="car_frame_rz" type="revolute">
    <origin xyz="0.0 0.0 0.0" rpy="0 0 0"/>
    <axis xyz="0.0 0.0 1.0"/>
    <parent link="car_frame_intermediate_5"/>
    <child link="car_frame"/>
    <limit effort="1000.0" lower="-1000000000.0" upper="1000000000.0" velocity="10.0"/>
  </joint>
  <link name="car_frame">
    <inertial>
      <mass value="0.0"/>
      <inertia ixx="0.0" ixy="0.0" ixz="0.0" iyy="0.0" iyz="0.0" izz="0.0"/>
    </inertial>
  </link>
</robot>